<?xml version="1.0"?>
<robot name="gait_quadruped">
  <material name="torso_mat"><color rgba="0.15 0.15 0.18 1"/></material>
  <material name="hip_mat"><color rgba="0.5 0.1 0.8 1"/></material>
  <material name="thigh_mat"><color rgba="0.2 0.2 0.25 1"/></material>
  <material name="calf_mat"><color rgba="0.1 0.1 0.12 1"/></material>
  <material name="foot_mat"><color rgba="0.2 0.9 0.1 1"/></material>
  <link name="base_link">
    <inertial>
      <mass value="9.0"/>
      <origin xyz="0 0 0"/>
      <inertia ixx="0.037500" ixy="0" ixz="0" 
               iyy="0.159375" iyz="0" 
               izz="0.181875"/>
    </inertial>
    <visual>
      <origin xyz="0 0 0"/>
      <geometry>
        <box size="0.45 0.2 0.1"/>
      </geometry>
      <material name="torso_mat"/>
    </visual>
    <collision>
      <origin xyz="0 0 0"/>
      <geometry>
        <box size="0.45 0.2 0.1"/>
      </geometry>
    </collision>
  </link>
  <joint name="FL_hip_joint" type="revolute">
    <parent link="base_link"/>
    <child link="FL_hip_link"/>
    <origin xyz="0.185 0.130 0.000" rpy="0 0 0"/>
    <axis xyz="1 0 0"/>
    <limit effort="40.0" velocity="20.0" lower="-0.8" upper="0.8"/>
  </joint>
  <link name="FL_hip_link">
    <inertial>
      <mass value="0.6"/>
      <origin xyz="0 0.015 0"/>
      <inertia ixx="0.0003" ixy="0" ixz="0" iyy="0.0004" iyz="0" izz="0.0003"/>
    </inertial>
    <visual>
      <origin xyz="0 0 0" rpy="1.5708 0 0"/>
      <geometry>
        <cylinder radius="0.020" length="0.060"/>
      </geometry>
      <material name="hip_mat"/>
    </visual>
    <collision>
      <origin xyz="0 0 0" rpy="1.5708 0 0"/>
      <geometry>
        <cylinder radius="0.020" length="0.060"/>
      </geometry>
    </collision>
  </link>
  <joint name="FL_thigh_joint" type="revolute">
    <parent link="FL_hip_link"/>
    <child link="FL_thigh_link"/>
    <origin xyz="0.000 0.060 0.000" rpy="0 0 0"/>
    <axis xyz="0 1 0"/>
    <limit effort="60.0" velocity="15.0" lower="-1.2" upper="2.5"/>
  </joint>
  <link name="FL_thigh_link">
    <inertial>
      <mass value="1.0"/>
      <origin xyz="0 0 -0.110"/>
      <inertia ixx="0.004033" ixy="0" ixz="0" 
               iyy="0.004033" iyz="0" 
               izz="0.000162"/>
    </inertial>
    <visual>
      <origin xyz="0 0 -0.110" rpy="0 0 0"/>
      <geometry>
        <cylinder radius="0.018" length="0.220"/>
      </geometry>
      <material name="thigh_mat"/>
    </visual>
    <collision>
      <origin xyz="0 0 -0.110" rpy="0 0 0"/>
      <geometry>
        <cylinder radius="0.018" length="0.220"/>
      </geometry>
    </collision>
  </link>
  <joint name="FL_calf_joint" type="revolute">
    <parent link="FL_thigh_link"/>
    <child link="FL_calf_link"/>
    <origin xyz="0.000 0.000 -0.220" rpy="0 0 0"/>
    <axis xyz="0 1 0"/>
    <limit effort="60.0" velocity="20.0" lower="-2.5" upper="-0.2"/>
  </joint>
  <link name="FL_calf_link">
    <inertial>
      <mass value="0.4"/>
      <origin xyz="0 0 -0.110"/>
      <inertia ixx="0.001613" ixy="0" ixz="0" 
               iyy="0.001613" iyz="0" 
               izz="0.000039"/>
    </inertial>
    <visual>
      <origin xyz="0 0 -0.110" rpy="0 0 0"/>
      <geometry>
        <cylinder radius="0.014" length="0.220"/>
      </geometry>
      <material name="calf_mat"/>
    </visual>
    <collision>
      <origin xyz="0 0 -0.110" rpy="0 0 0"/>
      <geometry>
        <cylinder radius="0.014" length="0.220"/>
      </geometry>
    </collision>
  </link>
  <joint name="FL_foot_joint" type="fixed">
    <parent link="FL_calf_link"/>
    <child link="FL_foot"/>
    <origin xyz="0.000 0.000 -0.220" rpy="0 0 0"/>
  </joint>
  <link name="FL_foot">
    <inertial>
      <mass value="0.1"/>
      <origin xyz="0 0 0"/>
      <inertia ixx="0.00001" ixy="0" ixz="0" iyy="0.00001" iyz="0" izz="0.00001"/>
    </inertial>
    <visual>
      <origin xyz="0 0 0"/>
      <geometry>
        <sphere radius="0.020"/>
      </geometry>
      <material name="foot_mat"/>
    </visual>
    <collision>
      <origin xyz="0 0 0"/>
      <geometry>
        <sphere radius="0.020"/>
      </geometry>
      <contact>
        <lateral_friction value="1.2"/>
        <spinning_friction value="0.02"/>
        <rolling_friction value="0.02"/>
      </contact>
    </collision>
  </link>
  <joint name="FR_hip_joint" type="revolute">
    <parent link="base_link"/>
    <child link="FR_hip_link"/>
    <origin xyz="0.185 -0.130 0.000" rpy="0 0 0"/>
    <axis xyz="1 0 0"/>
    <limit effort="40.0" velocity="20.0" lower="-0.8" upper="0.8"/>
  </joint>
  <link name="FR_hip_link">
    <inertial>
      <mass value="0.6"/>
      <origin xyz="0 -0.015 0"/>
      <inertia ixx="0.0003" ixy="0" ixz="0" iyy="0.0004" iyz="0" izz="0.0003"/>
    </inertial>
    <visual>
      <origin xyz="0 0 0" rpy="1.5708 0 0"/>
      <geometry>
        <cylinder radius="0.020" length="0.060"/>
      </geometry>
      <material name="hip_mat"/>
    </visual>
    <collision>
      <origin xyz="0 0 0" rpy="1.5708 0 0"/>
      <geometry>
        <cylinder radius="0.020" length="0.060"/>
      </geometry>
    </collision>
  </link>
  <joint name="FR_thigh_joint" type="revolute">
    <parent link="FR_hip_link"/>
    <child link="FR_thigh_link"/>
    <origin xyz="0.000 -0.060 0.000" rpy="0 0 0"/>
    <axis xyz="0 1 0"/>
    <limit effort="60.0" velocity="15.0" lower="-1.2" upper="2.5"/>
  </joint>
  <link name="FR_thigh_link">
    <inertial>
      <mass value="1.0"/>
      <origin xyz="0 0 -0.110"/>
      <inertia ixx="0.004033" ixy="0" ixz="0" 
               iyy="0.004033" iyz="0" 
               izz="0.000162"/>
    </inertial>
    <visual>
      <origin xyz="0 0 -0.110" rpy="0 0 0"/>
      <geometry>
        <cylinder radius="0.018" length="0.220"/>
      </geometry>
      <material name="thigh_mat"/>
    </visual>
    <collision>
      <origin xyz="0 0 -0.110" rpy="0 0 0"/>
      <geometry>
        <cylinder radius="0.018" length="0.220"/>
      </geometry>
    </collision>
  </link>
  <joint name="FR_calf_joint" type="revolute">
    <parent link="FR_thigh_link"/>
    <child link="FR_calf_link"/>
    <origin xyz="0.000 0.000 -0.220" rpy="0 0 0"/>
    <axis xyz="0 1 0"/>
    <limit effort="60.0" velocity="20.0" lower="-2.5" upper="-0.2"/>
  </joint>
  <link name="FR_calf_link">
    <inertial>
      <mass value="0.4"/>
      <origin xyz="0 0 -0.110"/>
      <inertia ixx="0.001613" ixy="0" ixz="0" 
               iyy="0.001613" iyz="0" 
               izz="0.000039"/>
    </inertial>
    <visual>
      <origin xyz="0 0 -0.110" rpy="0 0 0"/>
      <geometry>
        <cylinder radius="0.014" length="0.220"/>
      </geometry>
      <material name="calf_mat"/>
    </visual>
    <collision>
      <origin xyz="0 0 -0.110" rpy="0 0 0"/>
      <geometry>
        <cylinder radius="0.014" length="0.220"/>
      </geometry>
    </collision>
  </link>
  <joint name="FR_foot_joint" type="fixed">
    <parent link="FR_calf_link"/>
    <child link="FR_foot"/>
    <origin xyz="0.000 0.000 -0.220" rpy="0 0 0"/>
  </joint>
  <link name="FR_foot">
    <inertial>
      <mass value="0.1"/>
      <origin xyz="0 0 0"/>
      <inertia ixx="0.00001" ixy="0" ixz="0" iyy="0.00001" iyz="0" izz="0.00001"/>
    </inertial>
    <visual>
      <origin xyz="0 0 0"/>
      <geometry>
        <sphere radius="0.020"/>
      </geometry>
      <material name="foot_mat"/>
    </visual>
    <collision>
      <origin xyz="0 0 0"/>
      <geometry>
        <sphere radius="0.020"/>
      </geometry>
      <contact>
        <lateral_friction value="1.2"/>
        <spinning_friction value="0.02"/>
        <rolling_friction value="0.02"/>
      </contact>
    </collision>
  </link>
  <joint name="RL_hip_joint" type="revolute">
    <parent link="base_link"/>
    <child link="RL_hip_link"/>
    <origin xyz="-0.185 0.130 0.000" rpy="0 0 0"/>
    <axis xyz="1 0 0"/>
    <limit effort="40.0" velocity="20.0" lower="-0.8" upper="0.8"/>
  </joint>
  <link name="RL_hip_link">
    <inertial>
      <mass value="0.6"/>
      <origin xyz="0 0.015 0"/>
      <inertia ixx="0.0003" ixy="0" ixz="0" iyy="0.0004" iyz="0" izz="0.0003"/>
    </inertial>
    <visual>
      <origin xyz="0 0 0" rpy="1.5708 0 0"/>
      <geometry>
        <cylinder radius="0.020" length="0.060"/>
      </geometry>
      <material name="hip_mat"/>
    </visual>
    <collision>
      <origin xyz="0 0 0" rpy="1.5708 0 0"/>
      <geometry>
        <cylinder radius="0.020" length="0.060"/>
      </geometry>
    </collision>
  </link>
  <joint name="RL_thigh_joint" type="revolute">
    <parent link="RL_hip_link"/>
    <child link="RL_thigh_link"/>
    <origin xyz="0.000 0.060 0.000" rpy="0 0 0"/>
    <axis xyz="0 1 0"/>
    <limit effort="60.0" velocity="15.0" lower="-1.2" upper="2.5"/>
  </joint>
  <link name="RL_thigh_link">
    <inertial>
      <mass value="1.0"/>
      <origin xyz="0 0 -0.110"/>
      <inertia ixx="0.004033" ixy="0" ixz="0" 
               iyy="0.004033" iyz="0" 
               izz="0.000162"/>
    </inertial>
    <visual>
      <origin xyz="0 0 -0.110" rpy="0 0 0"/>
      <geometry>
        <cylinder radius="0.018" length="0.220"/>
      </geometry>
      <material name="thigh_mat"/>
    </visual>
    <collision>
      <origin xyz="0 0 -0.110" rpy="0 0 0"/>
      <geometry>
        <cylinder radius="0.018" length="0.220"/>
      </geometry>
    </collision>
  </link>
  <joint name="RL_calf_joint" type="revolute">
    <parent link="RL_thigh_link"/>
    <child link="RL_calf_link"/>
    <origin xyz="0.000 0.000 -0.220" rpy="0 0 0"/>
    <axis xyz="0 1 0"/>
    <limit effort="60.0" velocity="20.0" lower="-2.5" upper="-0.2"/>
  </joint>
  <link name="RL_calf_link">
    <inertial>
      <mass value="0.4"/>
      <origin xyz="0 0 -0.110"/>
      <inertia ixx="0.001613" ixy="0" ixz="0" 
               iyy="0.001613" iyz="0" 
               izz="0.000039"/>
    </inertial>
    <visual>
      <origin xyz="0 0 -0.110" rpy="0 0 0"/>
      <geometry>
        <cylinder radius="0.014" length="0.220"/>
      </geometry>
      <material name="calf_mat"/>
    </visual>
    <collision>
      <origin xyz="0 0 -0.110" rpy="0 0 0"/>
      <geometry>
        <cylinder radius="0.014" length="0.220"/>
      </geometry>
    </collision>
  </link>
  <joint name="RL_foot_joint" type="fixed">
    <parent link="RL_calf_link"/>
    <child link="RL_foot"/>
    <origin xyz="0.000 0.000 -0.220" rpy="0 0 0"/>
  </joint>
  <link name="RL_foot">
    <inertial>
      <mass value="0.1"/>
      <origin xyz="0 0 0"/>
      <inertia ixx="0.00001" ixy="0" ixz="0" iyy="0.00001" iyz="0" izz="0.00001"/>
    </inertial>
    <visual>
      <origin xyz="0 0 0"/>
      <geometry>
        <sphere radius="0.020"/>
      </geometry>
      <material name="foot_mat"/>
    </visual>
    <collision>
      <origin xyz="0 0 0"/>
      <geometry>
        <sphere radius="0.020"/>
      </geometry>
      <contact>
        <lateral_friction value="1.2"/>
        <spinning_friction value="0.02"/>
        <rolling_friction value="0.02"/>
      </contact>
    </collision>
  </link>
  <joint name="RR_hip_joint" type="revolute">
    <parent link="base_link"/>
    <child link="RR_hip_link"/>
    <origin xyz="-0.185 -0.130 0.000" rpy="0 0 0"/>
    <axis xyz="1 0 0"/>
    <limit effort="40.0" velocity="20.0" lower="-0.8" upper="0.8"/>
  </joint>
  <link name="RR_hip_link">
    <inertial>
      <mass value="0.6"/>
      <origin xyz="0 -0.015 0"/>
      <inertia ixx="0.0003" ixy="0" ixz="0" iyy="0.0004" iyz="0" izz="0.0003"/>
    </inertial>
    <visual>
      <origin xyz="0 0 0" rpy="1.5708 0 0"/>
      <geometry>
        <cylinder radius="0.020" length="0.060"/>
      </geometry>
      <material name="hip_mat"/>
    </visual>
    <collision>
      <origin xyz="0 0 0" rpy="1.5708 0 0"/>
      <geometry>
        <cylinder radius="0.020" length="0.060"/>
      </geometry>
    </collision>
  </link>
  <joint name="RR_thigh_joint" type="revolute">
    <parent link="RR_hip_link"/>
    <child link="RR_thigh_link"/>
    <origin xyz="0.000 -0.060 0.000" rpy="0 0 0"/>
    <axis xyz="0 1 0"/>
    <limit effort="60.0" velocity="15.0" lower="-1.2" upper="2.5"/>
  </joint>
  <link name="RR_thigh_link">
    <inertial>
      <mass value="1.0"/>
      <origin xyz="0 0 -0.110"/>
      <inertia ixx="0.004033" ixy="0" ixz="0" 
               iyy="0.004033" iyz="0" 
               izz="0.000162"/>
    </inertial>
    <visual>
      <origin xyz="0 0 -0.110" rpy="0 0 0"/>
      <geometry>
        <cylinder radius="0.018" length="0.220"/>
      </geometry>
      <material name="thigh_mat"/>
    </visual>
    <collision>
      <origin xyz="0 0 -0.110" rpy="0 0 0"/>
      <geometry>
        <cylinder radius="0.018" length="0.220"/>
      </geometry>
    </collision>
  </link>
  <joint name="RR_calf_joint" type="revolute">
    <parent link="RR_thigh_link"/>
    <child link="RR_calf_link"/>
    <origin xyz="0.000 0.000 -0.220" rpy="0 0 0"/>
    <axis xyz="0 1 0"/>
    <limit effort="60.0" velocity="20.0" lower="-2.5" upper="-0.2"/>
  </joint>
  <link name="RR_calf_link">
    <inertial>
      <mass value="0.4"/>
      <origin xyz="0 0 -0.110"/>
      <inertia ixx="0.001613" ixy="0" ixz="0" 
               iyy="0.001613" iyz="0" 
               izz="0.000039"/>
    </inertial>
    <visual>
      <origin xyz="0 0 -0.110" rpy="0 0 0"/>
      <geometry>
        <cylinder radius="0.014" length="0.220"/>
      </geometry>
      <material name="calf_mat"/>
    </visual>
    <collision>
      <origin xyz="0 0 -0.110" rpy="0 0 0"/>
      <geometry>
        <cylinder radius="0.014" length="0.220"/>
      </geometry>
    </collision>
  </link>
  <joint name="RR_foot_joint" type="fixed">
    <parent link="RR_calf_link"/>
    <child link="RR_foot"/>
    <origin xyz="0.000 0.000 -0.220" rpy="0 0 0"/>
  </joint>
  <link name="RR_foot">
    <inertial>
      <mass value="0.1"/>
      <origin xyz="0 0 0"/>
      <inertia ixx="0.00001" ixy="0" ixz="0" iyy="0.00001" iyz="0" izz="0.00001"/>
    </inertial>
    <visual>
      <origin xyz="0 0 0"/>
      <geometry>
        <sphere radius="0.020"/>
      </geometry>
      <material name="foot_mat"/>
    </visual>
    <collision>
      <origin xyz="0 0 0"/>
      <geometry>
        <sphere radius="0.020"/>
      </geometry>
      <contact>
        <lateral_friction value="1.2"/>
        <spinning_friction value="0.02"/>
        <rolling_friction value="0.02"/>
      </contact>
    </collision>
  </link>
</robot>